ERROR:root:verify current token exception : 'expires_on'
Traceback (most recent call last):
  File "script.py", line 61, in verify_cloudflare_token
    token_expiration_date = data['result']['expires_on']
KeyError: 'expires_on'
ERROR:root:-------------------------------
Traceback (most recent call last):
  File "script.py", line 61, in verify_cloudflare_token
    token_expiration_date = data['result']['expires_on']
KeyError: 'expires_on'
ERROR:root:fetching records exception : HTTP Error 403: Forbidden
Traceback (most recent call last):
  File "script.py", line 183, in main
    with urlopen(request, timeout=20) as response:
  File "/usr/lib/python3.8/urllib/request.py", line 222, in urlopen
    return opener.open(url, data, timeout)
  File "/usr/lib/python3.8/urllib/request.py", line 531, in open
    response = meth(req, response)
  File "/usr/lib/python3.8/urllib/request.py", line 640, in http_response
    response = self.parent.error(
  File "/usr/lib/python3.8/urllib/request.py", line 569, in error
    return self._call_chain(*args)
  File "/usr/lib/python3.8/urllib/request.py", line 502, in _call_chain
    result = func(*args)
  File "/usr/lib/python3.8/urllib/request.py", line 649, in http_error_default
    raise HTTPError(req.full_url, code, msg, hdrs, fp)
urllib.error.HTTPError: HTTP Error 403: Forbidden
ERROR:root:-------------------------------
Traceback (most recent call last):
  File "script.py", line 183, in main
    with urlopen(request, timeout=20) as response:
  File "/usr/lib/python3.8/urllib/request.py", line 222, in urlopen
    return opener.open(url, data, timeout)
  File "/usr/lib/python3.8/urllib/request.py", line 531, in open
    response = meth(req, response)
  File "/usr/lib/python3.8/urllib/request.py", line 640, in http_response
    response = self.parent.error(
  File "/usr/lib/python3.8/urllib/request.py", line 569, in error
    return self._call_chain(*args)
  File "/usr/lib/python3.8/urllib/request.py", line 502, in _call_chain
    result = func(*args)
  File "/usr/lib/python3.8/urllib/request.py", line 649, in http_error_default
    raise HTTPError(req.full_url, code, msg, hdrs, fp)
urllib.error.HTTPError: HTTP Error 403: Forbidden
ERROR:root:fetching records exception : HTTP Error 403: Forbidden
Traceback (most recent call last):
  File "script.py", line 184, in main
    with urlopen(request, timeout=20) as response:
  File "/usr/lib/python3.8/urllib/request.py", line 222, in urlopen
    return opener.open(url, data, timeout)
  File "/usr/lib/python3.8/urllib/request.py", line 531, in open
    response = meth(req, response)
  File "/usr/lib/python3.8/urllib/request.py", line 640, in http_response
    response = self.parent.error(
  File "/usr/lib/python3.8/urllib/request.py", line 569, in error
    return self._call_chain(*args)
  File "/usr/lib/python3.8/urllib/request.py", line 502, in _call_chain
    result = func(*args)
  File "/usr/lib/python3.8/urllib/request.py", line 649, in http_error_default
    raise HTTPError(req.full_url, code, msg, hdrs, fp)
urllib.error.HTTPError: HTTP Error 403: Forbidden
ERROR:root:-------------------------------
Traceback (most recent call last):
  File "script.py", line 184, in main
    with urlopen(request, timeout=20) as response:
  File "/usr/lib/python3.8/urllib/request.py", line 222, in urlopen
    return opener.open(url, data, timeout)
  File "/usr/lib/python3.8/urllib/request.py", line 531, in open
    response = meth(req, response)
  File "/usr/lib/python3.8/urllib/request.py", line 640, in http_response
    response = self.parent.error(
  File "/usr/lib/python3.8/urllib/request.py", line 569, in error
    return self._call_chain(*args)
  File "/usr/lib/python3.8/urllib/request.py", line 502, in _call_chain
    result = func(*args)
  File "/usr/lib/python3.8/urllib/request.py", line 649, in http_error_default
    raise HTTPError(req.full_url, code, msg, hdrs, fp)
urllib.error.HTTPError: HTTP Error 403: Forbidden
ERROR:root:fetching records exception : HTTP Error 403: Forbidden
Traceback (most recent call last):
  File "script.py", line 185, in main
    with urlopen(request, timeout=20) as response:
  File "/usr/lib/python3.8/urllib/request.py", line 222, in urlopen
    return opener.open(url, data, timeout)
  File "/usr/lib/python3.8/urllib/request.py", line 531, in open
    response = meth(req, response)
  File "/usr/lib/python3.8/urllib/request.py", line 640, in http_response
    response = self.parent.error(
  File "/usr/lib/python3.8/urllib/request.py", line 569, in error
    return self._call_chain(*args)
  File "/usr/lib/python3.8/urllib/request.py", line 502, in _call_chain
    result = func(*args)
  File "/usr/lib/python3.8/urllib/request.py", line 649, in http_error_default
    raise HTTPError(req.full_url, code, msg, hdrs, fp)
urllib.error.HTTPError: HTTP Error 403: Forbidden
ERROR:root:-------------------------------
Traceback (most recent call last):
  File "script.py", line 185, in main
    with urlopen(request, timeout=20) as response:
  File "/usr/lib/python3.8/urllib/request.py", line 222, in urlopen
    return opener.open(url, data, timeout)
  File "/usr/lib/python3.8/urllib/request.py", line 531, in open
    response = meth(req, response)
  File "/usr/lib/python3.8/urllib/request.py", line 640, in http_response
    response = self.parent.error(
  File "/usr/lib/python3.8/urllib/request.py", line 569, in error
    return self._call_chain(*args)
  File "/usr/lib/python3.8/urllib/request.py", line 502, in _call_chain
    result = func(*args)
  File "/usr/lib/python3.8/urllib/request.py", line 649, in http_error_default
    raise HTTPError(req.full_url, code, msg, hdrs, fp)
urllib.error.HTTPError: HTTP Error 403: Forbidden
ERROR:root:fetching records exception : HTTP Error 403: Forbidden
Traceback (most recent call last):
  File "script.py", line 184, in main
    with urlopen(request, timeout=20) as response:
  File "/usr/lib/python3.8/urllib/request.py", line 222, in urlopen
    return opener.open(url, data, timeout)
  File "/usr/lib/python3.8/urllib/request.py", line 531, in open
    response = meth(req, response)
  File "/usr/lib/python3.8/urllib/request.py", line 640, in http_response
    response = self.parent.error(
  File "/usr/lib/python3.8/urllib/request.py", line 569, in error
    return self._call_chain(*args)
  File "/usr/lib/python3.8/urllib/request.py", line 502, in _call_chain
    result = func(*args)
  File "/usr/lib/python3.8/urllib/request.py", line 649, in http_error_default
    raise HTTPError(req.full_url, code, msg, hdrs, fp)
urllib.error.HTTPError: HTTP Error 403: Forbidden
ERROR:root:-------------------------------
Traceback (most recent call last):
  File "script.py", line 184, in main
    with urlopen(request, timeout=20) as response:
  File "/usr/lib/python3.8/urllib/request.py", line 222, in urlopen
    return opener.open(url, data, timeout)
  File "/usr/lib/python3.8/urllib/request.py", line 531, in open
    response = meth(req, response)
  File "/usr/lib/python3.8/urllib/request.py", line 640, in http_response
    response = self.parent.error(
  File "/usr/lib/python3.8/urllib/request.py", line 569, in error
    return self._call_chain(*args)
  File "/usr/lib/python3.8/urllib/request.py", line 502, in _call_chain
    result = func(*args)
  File "/usr/lib/python3.8/urllib/request.py", line 649, in http_error_default
    raise HTTPError(req.full_url, code, msg, hdrs, fp)
urllib.error.HTTPError: HTTP Error 403: Forbidden
INFO:root:the requested domain is already taken
ERROR:root:creating new record apported :'url'
Traceback (most recent call last):
  File "script.py", line 209, in main
    url = CONFIG['url'] + "/xml-api/cpanel?cpanel_xmlapi_module=ZoneEdit&cpanel_xmlapi_func=add_zone_record&cpanel_xmlapi_apiversion=2&domain="+ domain + "&name=" + record_name + "&type=" + record_type + "&ttl=" + ttl + "&address=" + ip
KeyError: 'url'
ERROR:root:fetching records exception : HTTP Error 403: Forbidden
Traceback (most recent call last):
  File "script.py", line 184, in main
    with urlopen(request, timeout=20) as response:
  File "/usr/lib/python3.8/urllib/request.py", line 222, in urlopen
    return opener.open(url, data, timeout)
  File "/usr/lib/python3.8/urllib/request.py", line 531, in open
    response = meth(req, response)
  File "/usr/lib/python3.8/urllib/request.py", line 640, in http_response
    response = self.parent.error(
  File "/usr/lib/python3.8/urllib/request.py", line 569, in error
    return self._call_chain(*args)
  File "/usr/lib/python3.8/urllib/request.py", line 502, in _call_chain
    result = func(*args)
  File "/usr/lib/python3.8/urllib/request.py", line 649, in http_error_default
    raise HTTPError(req.full_url, code, msg, hdrs, fp)
urllib.error.HTTPError: HTTP Error 403: Forbidden
ERROR:root:-------------------------------
Traceback (most recent call last):
  File "script.py", line 184, in main
    with urlopen(request, timeout=20) as response:
  File "/usr/lib/python3.8/urllib/request.py", line 222, in urlopen
    return opener.open(url, data, timeout)
  File "/usr/lib/python3.8/urllib/request.py", line 531, in open
    response = meth(req, response)
  File "/usr/lib/python3.8/urllib/request.py", line 640, in http_response
    response = self.parent.error(
  File "/usr/lib/python3.8/urllib/request.py", line 569, in error
    return self._call_chain(*args)
  File "/usr/lib/python3.8/urllib/request.py", line 502, in _call_chain
    result = func(*args)
  File "/usr/lib/python3.8/urllib/request.py", line 649, in http_error_default
    raise HTTPError(req.full_url, code, msg, hdrs, fp)
urllib.error.HTTPError: HTTP Error 403: Forbidden
